Workbook
Name _MailEndCompose: Sheet2!#REF!
Name Class_Type: #REF!
Name Days: #REF!
Name Faculty: #REF!
Name FacultyList: #REF!
Name Programme: #REF!
Name VenueList: #REF!

Sheet Timetable
A1: Module | B1: Class Type | C1: Template | D1: Group | E1: Day | F1: Start | G1: End | H1: Class Size | I1: Sector | J1: RoomGrouping | K1: Room1 | L1: Room2 | M1: StaffGrouping | N1: Staff1 | O1: Staff2 | P1: Tri Week | Q1: Recording Mode | R1: Remark | S1: FMTS Tri Start Week | T1: Activity Hostkey | U1: SIS Module Code | V1: Term | W1: Activity Type | X1: Duration | Y1: Staff Suitability ID | Z1: SIS Staff ID | AA1: SIS Staff ID | AB1: Zone Hoskey | AC1: Location Suitability ID | AD1: Location Hostkey | AE1: Location Hostkey
A2: SBE1109 | B2: Lectorial | C2: 1 | D2: All | E2: Wed | F2: 0900 | G2: 1100 | H2: 110 | I2: PUNGGOL | N2: PATRICK CHUA SOON KEONG | P2: 1,2,3,4,5,6 | Q2: A0 | R2: w ESE1109 | S2: 1 | T2: SBE1109-2520-ENG-UGRD-PU-LET/All | U2: =VLOOKUP(A2,'Course Code'!A:D,3,FALSE) -> SBE1109-2520-ENG-UGRD-PU | V2: =VLOOKUP(U2,'Course Code'!C:D, 2, FALSE) -> 2520 | W2: =VLOOKUP(B2,'Class Type'!$A$2:$B$25,2,FALSE) -> LET | X2: 6 | Y2: =VLOOKUP(F2,StaffGroup!$A$2:$B$35,2,FALSE) -> #N/A | AA2: =VLOOKUP(O2,Staff!A:B,2,FALSE) -> #N/A | AB2: =VLOOKUP(I2,Zone!$A$2:$B$101,2,FALSE) -> PUNGGOL | AC2: =VLOOKUP(J2,LocationGroup!$A$2:$B$35,2,FALSE) -> #N/A | AD2: =VLOOKUP(K2,Location!A:B,2,FALSE) -> #N/A | AE2: =VLOOKUP(L2,Location!A:B,2,FALSE) -> #N/A
A3: SBE1109 | B3: Lectorial | C3: 2 | D3: All | E3: Fri | F3: 0900 | G3: 1100 | H3: 110 | I3: PUNGGOL | N3: PATRICK CHUA SOON KEONG | P3: 1,2,3,4,5,6 | Q3: A0 | R3: w ESE1109 | S3: 1 | T3: SBE1109-2520-ENG-UGRD-PU-LET/All | U3: =VLOOKUP(A3,'Course Code'!A:D,3,FALSE) -> SBE1109-2520-ENG-UGRD-PU | V3: =VLOOKUP(U3,'Course Code'!C:D, 2, FALSE) -> 2520 | W3: =VLOOKUP(B3,'Class Type'!$A$2:$B$25,2,FALSE) -> LET | X3: 6 | Y3: =VLOOKUP(F3,StaffGroup!$A$2:$B$35,2,FALSE) -> #N/A | Z3: =VLOOKUP(N3,Staff!A:B,2,FALSE) -> A88114 | AA3: =VLOOKUP(O3,Staff!A:B,2,FALSE) -> #N/A | AB3: =VLOOKUP(I3,Zone!$A$2:$B$101,2,FALSE) -> PUNGGOL | AC3: =VLOOKUP(J3,LocationGroup!$A$2:$B$35,2,FALSE) -> #N/A | AD3: =VLOOKUP(K3,Location!A:B,2,FALSE) -> #N/A | AE3: =VLOOKUP(L3,Location!A:B,2,FALSE) -> #N/A
A4: SBE1109 | B4: Lectorial | C4: 3 | D4: All | E4: Fri | F4: 1000 | G4: 0930 | H4: 110 | I4: PUNGGOL | N4: AN HUI | P4: 8,9,10,11,12,13 | Q4: A0 | R4: w ESE1109 | S4: 1 | T4: SBE1109-2520-ENG-UGRD-PU-LET2/All | U4: =VLOOKUP(A4,'Course Code'!A:D,3,FALSE) -> SBE1109-2520-ENG-UGRD-PU | V4: =VLOOKUP(U4,'Course Code'!C:D, 2, FALSE) -> 2520 | W4: =VLOOKUP(B4,'Class Type'!$A$2:$B$25,2,FALSE) -> LET | X4: 6 | Y4: =VLOOKUP(F4,StaffGroup!$A$2:$B$35,2,FALSE) -> #N/A | Z4: =VLOOKUP(N4,Staff!A:B,2,FALSE) -> A88485 | AA4: =VLOOKUP(O4,Staff!A:B,2,FALSE) -> #N/A | AB4: =VLOOKUP(I4,Zone!$A$2:$B$101,2,FALSE) -> PUNGGOL | AC4: =VLOOKUP(J4,LocationGroup!$A$2:$B$35,2,FALSE) -> #N/A | AD4: =VLOOKUP(K4,Location!A:B,2,FALSE) -> #N/A | AE4: =VLOOKUP(L4,Location!A:B,2,FALSE) -> #N/A
A5: SBE1109 | B5: Tutorial | C5: 1 | D5: T1 | H5: 28 | I5: PUNGGOL | N5: PATRICK CHUA SOON KEONG | P5: 1,2,3,4,5,6 | S5: 1 | T5: SBE1109-2520-ENG-UGRD-PU-TUT/T1 | U5: =VLOOKUP(A5,'Course Code'!A:D,3,FALSE) -> SBE1109-2520-ENG-UGRD-PU | V5: =VLOOKUP(U5,'Course Code'!C:D, 2, FALSE) -> 2520 | W5: =VLOOKUP(B5,'Class Type'!$A$2:$B$25,2,FALSE) -> TUT | X5: 3 | Y5: =VLOOKUP(F5,StaffGroup!$A$2:$B$35,2,FALSE) -> #N/A | Z5: =VLOOKUP(N5,Staff!A:B,2,FALSE) -> A88114 | AA5: =VLOOKUP(O5,Staff!A:B,2,FALSE) -> #N/A | AB5: =VLOOKUP(I5,Zone!$A$2:$B$101,2,FALSE) -> PUNGGOL | AC5: =VLOOKUP(J5,LocationGroup!$A$2:$B$35,2,FALSE) -> #N/A | AD5: =VLOOKUP(K5,Location!A:B,2,FALSE) -> #N/A | AE5: =VLOOKUP(L5,Location!A:B,2,FALSE) -> #N/A
A6: SBE1109 | B6: Tutorial | C6: 1 | D6: T2 | H6: 28 | I6: PUNGGOL | N6: PATRICK CHUA SOON KEONG | P6: 1,2,3,4,5,6 | S6: 1 | T6: SBE1109-2520-ENG-UGRD-PU-TUT/T2 | U6: =VLOOKUP(A6,'Course Code'!A:D,3,FALSE) -> SBE1109-2520-ENG-UGRD-PU | V6: =VLOOKUP(U6,'Course Code'!C:D, 2, FALSE) -> 2520 | W6: =VLOOKUP(B6,'Class Type'!$A$2:$B$25,2,FALSE) -> TUT | X6: 3 | Y6: =VLOOKUP(F6,StaffGroup!$A$2:$B$35,2,FALSE) -> #N/A | Z6: =VLOOKUP(N6,Staff!A:B,2,FALSE) -> A88114 | AA6: =VLOOKUP(O6,Staff!A:B,2,FALSE) -> #N/A | AB6: =VLOOKUP(I6,Zone!$A$2:$B$101,2,FALSE) -> PUNGGOL | AC6: =VLOOKUP(J6,LocationGroup!$A$2:$B$35,2,FALSE) -> #N/A | AD6: =VLOOKUP(K6,Location!A:B,2,FALSE) -> #N/A | AE6: =VLOOKUP(L6,Location!A:B,2,FALSE) -> #N/A
A7: SBE1109 | B7: Tutorial | C7: 1 | D7: T3 | H7: 28 | I7: PUNGGOL | N7: PATRICK CHUA SOON KEONG | P7: 1,2,3,4,5,6 | S7: 1 | T7: SBE1109-2520-ENG-UGRD-PU-TUT/T3 | U7: =VLOOKUP(A7,'Course Code'!A:D,3,FALSE) -> SBE1109-2520-ENG-UGRD-PU | V7: =VLOOKUP(U7,'Course Code'!C:D, 2, FALSE) -> 2520 | W7: =VLOOKUP(B7,'Class Type'!$A$2:$B$25,2,FALSE) -> TUT | X7: 3 | Y7: =VLOOKUP(F7,StaffGroup!$A$2:$B$35,2,FALSE) -> #N/A | Z7: =VLOOKUP(N7,Staff!A:B,2,FALSE) -> A88114 | AA7: =VLOOKUP(O7,Staff!A:B,2,FALSE) -> #N/A | AB7: =VLOOKUP(I7,Zone!$A$2:$B$101,2,FALSE) -> PUNGGOL | AC7: =VLOOKUP(J7,LocationGroup!$A$2:$B$35,2,FALSE) -> #N/A | AD7: =VLOOKUP(K7,Location!A:B,2,FALSE) -> #N/A | AE7: =VLOOKUP(L7,Location!A:B,2,FALSE) -> #N/A
A8: SBE1109 | B8: Tutorial | C8: 1 | D8: T4 | H8: 28 | I8: PUNGGOL | N8: PATRICK CHUA SOON KEONG | P8: 1,2,3,4,5,6 | S8: 1 | T8: SBE1109-2520-ENG-UGRD-PU-TUT/T4 | U8: =VLOOKUP(A8,'Course Code'!A:D,3,FALSE) -> SBE1109-2520-ENG-UGRD-PU | V8: =VLOOKUP(U8,'Course Code'!C:D, 2, FALSE) -> 2520 | W8: =VLOOKUP(B8,'Class Type'!$A$2:$B$25,2,FALSE) -> TUT | X8: 3 | Y8: =VLOOKUP(F8,StaffGroup!$A$2:$B$35,2,FALSE) -> #N/A | Z8: =VLOOKUP(N8,Staff!A:B,2,FALSE) -> A88114 | AA8: =VLOOKUP(O8,Staff!A:B,2,FALSE) -> #N/A | AB8: =VLOOKUP(I8,Zone!$A$2:$B$101,2,FALSE) -> PUNGGOL | AC8: =VLOOKUP(J8,LocationGroup!$A$2:$B$35,2,FALSE) -> #N/A | AD8: =VLOOKUP(K8,Location!A:B,2,FALSE) -> #N/A | AE8: =VLOOKUP(L8,Location!A:B,2,FALSE) -> #N/A
A9: SBE1109 | B9: Tutorial | C9: 2 | D9: T1 | H9: 28 | I9: PUNGGOL | N9: AN HUI | P9: 8,9,10,11,12,13 | S9: 1 | T9: SBE1109-2520-ENG-UGRD-PU-TUT2/T1 | U9: =VLOOKUP(A9,'Course Code'!A:D,3,FALSE) -> SBE1109-2520-ENG-UGRD-PU | V9: =VLOOKUP(U9,'Course Code'!C:D, 2, FALSE) -> 2520 | W9: =VLOOKUP(B9,'Class Type'!$A$2:$B$25,2,FALSE) -> TUT | X9: 3 | Y9: =VLOOKUP(F9,StaffGroup!$A$2:$B$35,2,FALSE) -> #N/A | Z9: =VLOOKUP(N9,Staff!A:B,2,FALSE) -> A88485 | AA9: =VLOOKUP(O9,Staff!A:B,2,FALSE) -> #N/A | AB9: =VLOOKUP(I9,Zone!$A$2:$B$101,2,FALSE) -> PUNGGOL | AC9: =VLOOKUP(J9,LocationGroup!$A$2:$B$35,2,FALSE) -> #N/A | AD9: =VLOOKUP(K9,Location!A:B,2,FALSE) -> #N/A | AE9: =VLOOKUP(L9,Location!A:B,2,FALSE) -> #N/A
A10: SBE1109 | B10: Tutorial | C10: 2 | D10: T2 | H10: 28 | I10: PUNGGOL | N10: AN HUI | P10: 8,9,10,11,12,13 | S10: 1 | T10: SBE1109-2520-ENG-UGRD-PU-TUT2/T2 | U10: =VLOOKUP(A10,'Course Code'!A:D,3,FALSE) -> SBE1109-2520-ENG-UGRD-PU | V10: =VLOOKUP(U10,'Course Code'!C:D, 2, FALSE) -> 2520 | W10: =VLOOKUP(B10,'Class Type'!$A$2:$B$25,2,FALSE) -> TUT | X10: 3 | Y10: =VLOOKUP(F10,StaffGroup!$A$2:$B$35,2,FALSE) -> #N/A | Z10: =VLOOKUP(N10,Staff!A:B,2,FALSE) -> A88485 | AA10: =VLOOKUP(O10,Staff!A:B,2,FALSE) -> #N/A | AB10: =VLOOKUP(I10,Zone!$A$2:$B$101,2,FALSE) -> PUNGGOL | AC10: =VLOOKUP(J10,LocationGroup!$A$2:$B$35,2,FALSE) -> #N/A | AD10: =VLOOKUP(K10,Location!A:B,2,FALSE) -> #N/A | AE10: =VLOOKUP(L10,Location!A:B,2,FALSE) -> #N/A
A11: SBE1109 | B11: Tutorial | C11: 2 | D11: T3 | H11: 28 | I11: PUNGGOL | N11: AN HUI | P11: 8,9,10,11,12,13 | S11: 1 | T11: SBE1109-2520-ENG-UGRD-PU-TUT2/T3 | U11: =VLOOKUP(A11,'Course Code'!A:D,3,FALSE) -> SBE1109-2520-ENG-UGRD-PU | V11: =VLOOKUP(U11,'Course Code'!C:D, 2, FALSE) -> 2520 | W11: =VLOOKUP(B11,'Class Type'!$A$2:$B$25,2,FALSE) -> TUT | X11: 3 | Y11: =VLOOKUP(F11,StaffGroup!$A$2:$B$35,2,FALSE) -> #N/A | Z11: =VLOOKUP(N11,Staff!A:B,2,FALSE) -> A88485 | AA11: =VLOOKUP(O11,Staff!A:B,2,FALSE) -> #N/A | AB11: =VLOOKUP(I11,Zone!$A$2:$B$101,2,FALSE) -> PUNGGOL | AC11: =VLOOKUP(J11,LocationGroup!$A$2:$B$35,2,FALSE) -> #N/A | AD11: =VLOOKUP(K11,Location!A:B,2,FALSE) -> #N/A | AE11: =VLOOKUP(L11,Location!A:B,2,FALSE) -> #N/A
A12: SBE1109 | B12: Tutorial | C12: 2 | D12: T4 | H12: 28 | I12: PUNGGOL | N12: AN HUI | P12: 8,9,10,11,12,13 | S12: 1 | T12: SBE1109-2520-ENG-UGRD-PU-TUT2/T4 | U12: =VLOOKUP(A12,'Course Code'!A:D,3,FALSE) -> SBE1109-2520-ENG-UGRD-PU | V12: =VLOOKUP(U12,'Course Code'!C:D, 2, FALSE) -> 2520 | W12: =VLOOKUP(B12,'Class Type'!$A$2:$B$25,2,FALSE) -> TUT | X12: 3 | Y12: =VLOOKUP(F12,StaffGroup!$A$2:$B$35,2,FALSE) -> #N/A | Z12: =VLOOKUP(N12,Staff!A:B,2,FALSE) -> A88485 | AA12: =VLOOKUP(O12,Staff!A:B,2,FALSE) -> #N/A | AB12: =VLOOKUP(I12,Zone!$A$2:$B$101,2,FALSE) -> PUNGGOL | AC12: =VLOOKUP(J12,LocationGroup!$A$2:$B$35,2,FALSE) -> #N/A | AD12: =VLOOKUP(K12,Location!A:B,2,FALSE) -> #N/A | AE12: =VLOOKUP(L12,Location!A:B,2,FALSE) -> #N/A
A13: SBE1109 | B13: Quiz | C13: 1 | D13: Q1 | H13: 110 | I13: PUNGGOL | N13: PATRICK CHUA SOON KEONG | P13: 4 | R13: w ESE1109 | S13: 1 | T13: SBE1109-2520-ENG-UGRD-PU-QUZ/Q1 | U13: =VLOOKUP(A13,'Course Code'!A:D,3,FALSE) -> SBE1109-2520-ENG-UGRD-PU | V13: =VLOOKUP(U13,'Course Code'!C:D, 2, FALSE) -> 2520 | W13: =VLOOKUP(B13,'Class Type'!$A$2:$B$25,2,FALSE) -> QUZ | X13: 4 | Y13: =VLOOKUP(F13,StaffGroup!$A$2:$B$35,2,FALSE) -> #N/A | Z13: =VLOOKUP(N13,Staff!A:B,2,FALSE) -> A88114 | AA13: =VLOOKUP(O13,Staff!A:B,2,FALSE) -> #N/A | AB13: =VLOOKUP(I13,Zone!$A$2:$B$101,2,FALSE) -> PUNGGOL | AC13: =VLOOKUP(J13,LocationGroup!$A$2:$B$35,2,FALSE) -> #N/A | AD13: =VLOOKUP(K13,Location!A:B,2,FALSE) -> #N/A | AE13: =VLOOKUP(L13,Location!A:B,2,FALSE) -> #N/A
A14: SBE1109 | B14: Quiz | C14: 2 | D14: Q1 | H14: 110 | I14: PUNGGOL | N14: PATRICK CHUA SOON KEONG | P14: 8 | R14: w ESE1109 | S14: 1 | T14: SBE1109-2520-ENG-UGRD-PU-QUZ2/Q1 | U14: =VLOOKUP(A14,'Course Code'!A:D,3,FALSE) -> SBE1109-2520-ENG-UGRD-PU | V14: =VLOOKUP(U14,'Course Code'!C:D, 2, FALSE) -> 2520 | W14: =VLOOKUP(B14,'Class Type'!$A$2:$B$25,2,FALSE) -> QUZ | X14: 4 | Y14: =VLOOKUP(F14,StaffGroup!$A$2:$B$35,2,FALSE) -> #N/A | Z14: =VLOOKUP(N14,Staff!A:B,2,FALSE) -> A88114 | AA14: =VLOOKUP(O14,Staff!A:B,2,FALSE) -> #N/A | AB14: =VLOOKUP(I14,Zone!$A$2:$B$101,2,FALSE) -> PUNGGOL | AC14: =VLOOKUP(J14,LocationGroup!$A$2:$B$35,2,FALSE) -> #N/A | AD14: =VLOOKUP(K14,Location!A:B,2,FALSE) -> #N/A | AE14: =VLOOKUP(L14,Location!A:B,2,FALSE) -> #N/A
A15: SBE1109 | B15: Quiz | C15: 3 | D15: Q1 | H15: 110 | I15: PUNGGOL | N15: AN HUI | P15: 13 | R15: w ESE1109 | S15: 1 | T15: SBE1109-2520-ENG-UGRD-PU-QUZ3/Q1 | U15: =VLOOKUP(A15,'Course Code'!A:D,3,FALSE) -> SBE1109-2520-ENG-UGRD-PU | V15: =VLOOKUP(U15,'Course Code'!C:D, 2, FALSE) -> 2520 | W15: =VLOOKUP(B15,'Class Type'!$A$2:$B$25,2,FALSE) -> QUZ | X15: 4 | Y15: =VLOOKUP(F15,StaffGroup!$A$2:$B$35,2,FALSE) -> #N/A | Z15: =VLOOKUP(N15,Staff!A:B,2,FALSE) -> A88485 | AA15: =VLOOKUP(O15,Staff!A:B,2,FALSE) -> #N/A | AB15: =VLOOKUP(I15,Zone!$A$2:$B$101,2,FALSE) -> PUNGGOL | AC15: =VLOOKUP(J15,LocationGroup!$A$2:$B$35,2,FALSE) -> #N/A | AD15: =VLOOKUP(K15,Location!A:B,2,FALSE) -> #N/A | AE15: =VLOOKUP(L15,Location!A:B,2,FALSE) -> #N/A
A16: SBE1111 | B16: Lectorial | C16: 1 | D16: L1 | H16: 55 | I16: PUNGGOL | N16: SHEN LU | P16: 1,2,5 | Q16: A0 | R16: L1/L2 combine | S16: 1 | T16: SBE1111-2520-ENG-UGRD-PU-LET/L1 | U16: =VLOOKUP(A16,'Course Code'!A:D,3,FALSE) -> SBE1111-2520-ENG-UGRD-PU | V16: =VLOOKUP(U16,'Course Code'!C:D, 2, FALSE) -> 2520 | W16: =VLOOKUP(B16,'Class Type'!$A$2:$B$25,2,FALSE) -> LET | X16: 4 | Y16: =VLOOKUP(F16,StaffGroup!$A$2:$B$35,2,FALSE) -> #N/A | Z16: =VLOOKUP(N16,Staff!A:B,2,FALSE) -> A88575 | AA16: =VLOOKUP(O16,Staff!A:B,2,FALSE) -> #N/A | AB16: =VLOOKUP(I16,Zone!$A$2:$B$101,2,FALSE) -> PUNGGOL | AC16: =VLOOKUP(J16,LocationGroup!$A$2:$B$35,2,FALSE) -> #N/A | AD16: =VLOOKUP(K16,Location!A:B,2,FALSE) -> #N/A | AE16: =VLOOKUP(L16,Location!A:B,2,FALSE) -> #N/A
A17: SBE1111 | B17: Lectorial | C17: 1 | D17: L2 | H17: 55 | I17: PUNGGOL | N17: SHEN LU | P17: 1,2,5 | Q17: A0 | R17: L1/L2 combine | S17: 1 | T17: SBE1111-2520-ENG-UGRD-PU-LET/L2 | U17: =VLOOKUP(A17,'Course Code'!A:D,3,FALSE) -> SBE1111-2520-ENG-UGRD-PU | V17: =VLOOKUP(U17,'Course Code'!C:D, 2, FALSE) -> 2520 | W17: =VLOOKUP(B17,'Class Type'!$A$2:$B$25,2,FALSE) -> LET | X17: 18 | Y17: =VLOOKUP(F17,StaffGroup!$A$2:$B$35,2,FALSE) -> #N/A | Z17: =VLOOKUP(N17,Staff!A:B,2,FALSE) -> A88575 | AA17: =VLOOKUP(O17,Staff!A:B,2,FALSE) -> #N/A | AB17: =VLOOKUP(I17,Zone!$A$2:$B$101,2,FALSE) -> PUNGGOL | AC17: =VLOOKUP(J17,LocationGroup!$A$2:$B$35,2,FALSE) -> #N/A | AD17: =VLOOKUP(K17,Location!A:B,2,FALSE) -> #N/A | AE17: =VLOOKUP(L17,Location!A:B,2,FALSE) -> #N/A
A18: SBE1111 | B18: Lectorial | C18: 2 | D18: L1 | H18: 55 | I18: PUNGGOL | N18: SHEN LU | P18: 14 | Q18: A0 | S18: 1 | T18: SBE1111-2520-ENG-UGRD-PU-LET2/L1 | U18: =VLOOKUP(A18,'Course Code'!A:D,3,FALSE) -> SBE1111-2520-ENG-UGRD-PU | V18: =VLOOKUP(U18,'Course Code'!C:D, 2, FALSE) -> 2520 | W18: =VLOOKUP(B18,'Class Type'!$A$2:$B$25,2,FALSE) -> LET | X18: 18 | Y18: =VLOOKUP(F18,StaffGroup!$A$2:$B$35,2,FALSE) -> #N/A | Z18: =VLOOKUP(N18,Staff!A:B,2,FALSE) -> A88575 | AA18: =VLOOKUP(O18,Staff!A:B,2,FALSE) -> #N/A | AB18: =VLOOKUP(I18,Zone!$A$2:$B$101,2,FALSE) -> PUNGGOL | AC18: =VLOOKUP(J18,LocationGroup!$A$2:$B$35,2,FALSE) -> #N/A | AD18: =VLOOKUP(K18,Location!A:B,2,FALSE) -> #N/A | AE18: =VLOOKUP(L18,Location!A:B,2,FALSE) -> #N/A
A19: SBE1111 | B19: Lectorial | C19: 2 | D19: L2 | H19: 55 | I19: PUNGGOL | N19: SHEN LU | P19: 14 | Q19: A0 | S19: 1 | T19: SBE1111-2520-ENG-UGRD-PU-LET2/L2 | U19: =VLOOKUP(A19,'Course Code'!A:D,3,FALSE) -> SBE1111-2520-ENG-UGRD-PU | V19: =VLOOKUP(U19,'Course Code'!C:D, 2, FALSE) -> 2520 | W19: =VLOOKUP(B19,'Class Type'!$A$2:$B$25,2,FALSE) -> LET | X19: 18 | Y19: =VLOOKUP(F19,StaffGroup!$A$2:$B$35,2,FALSE) -> #N/A | Z19: =VLOOKUP(N19,Staff!A:B,2,FALSE) -> A88575 | AA19: =VLOOKUP(O19,Staff!A:B,2,FALSE) -> #N/A | AB19: =VLOOKUP(I19,Zone!$A$2:$B$101,2,FALSE) -> PUNGGOL | AC19: =VLOOKUP(J19,LocationGroup!$A$2:$B$35,2,FALSE) -> #N/A | AD19: =VLOOKUP(K19,Location!A:B,2,FALSE) -> #N/A | AE19: =VLOOKUP(L19,Location!A:B,2,FALSE) -> #N/A
A20: SBE2112 | B20: Lectorial | C20: 1 | D20: All | H20: 110 | I20: PUNGGOL | N20: LEE KWEE HIONG | P20: 1,2,3,4,6 | Q20: A0 | R20: w ESE2103 | S20: 1 | T20: SBE2112-2520-ENG-UGRD-PU-LET/All | U20: =VLOOKUP(A20,'Course Code'!A:D,3,FALSE) -> SBE2112-2520-ENG-UGRD-PU | V20: =VLOOKUP(U20,'Course Code'!C:D, 2, FALSE) -> 2520 | W20: =VLOOKUP(B20,'Class Type'!$A$2:$B$25,2,FALSE) -> LET | X20: 6 | Y20: =VLOOKUP(F20,StaffGroup!$A$2:$B$35,2,FALSE) -> #N/A | Z20: =VLOOKUP(N20,Staff!A:B,2,FALSE) -> A88165 | AA20: =VLOOKUP(O20,Staff!A:B,2,FALSE) -> #N/A | AB20: =VLOOKUP(I20,Zone!$A$2:$B$101,2,FALSE) -> PUNGGOL | AC20: =VLOOKUP(J20,LocationGroup!$A$2:$B$35,2,FALSE) -> #N/A | AD20: =VLOOKUP(K20,Location!A:B,2,FALSE) -> #N/A | AE20: =VLOOKUP(L20,Location!A:B,2,FALSE) -> #N/A
A21: SBE2112 | B21: Lectorial | C21: 2 | D21: All | H21: 110 | I21: PUNGGOL | N21: LEE KWEE HIONG | P21: 5 | Q21: A0 | R21: w ESE2103 | S21: 1 | T21: SBE2112-2520-ENG-UGRD-PU-LET2/All | U21: =VLOOKUP(A21,'Course Code'!A:D,3,FALSE) -> SBE2112-2520-ENG-UGRD-PU | V21: =VLOOKUP(U21,'Course Code'!C:D, 2, FALSE) -> 2520 | W21: =VLOOKUP(B21,'Class Type'!$A$2:$B$25,2,FALSE) -> LET | X21: 6 | Y21: =VLOOKUP(F21,StaffGroup!$A$2:$B$35,2,FALSE) -> #N/A | Z21: =VLOOKUP(N21,Staff!A:B,2,FALSE) -> A88165 | AA21: =VLOOKUP(O21,Staff!A:B,2,FALSE) -> #N/A | AB21: =VLOOKUP(I21,Zone!$A$2:$B$101,2,FALSE) -> PUNGGOL | AC21: =VLOOKUP(J21,LocationGroup!$A$2:$B$35,2,FALSE) -> #N/A | AD21: =VLOOKUP(K21,Location!A:B,2,FALSE) -> #N/A | AE21: =VLOOKUP(L21,Location!A:B,2,FALSE) -> #N/A
A22: SBE2112 | B22: Lectorial | C22: 3 | D22: All | H22: 110 | I22: PUNGGOL | N22: NADARAJAN SIVAKUMAR | P22: 8,10,12,13 | S22: 1 | T22: SBE2112-2520-ENG-UGRD-PU-LET3/All | U22: =VLOOKUP(A22,'Course Code'!A:D,3,FALSE) -> SBE2112-2520-ENG-UGRD-PU | V22: =VLOOKUP(U22,'Course Code'!C:D, 2, FALSE) -> 2520 | W22: =VLOOKUP(B22,'Class Type'!$A$2:$B$25,2,FALSE) -> LET | X22: 6 | Y22: =VLOOKUP(F22,StaffGroup!$A$2:$B$35,2,FALSE) -> #N/A | Z22: =VLOOKUP(N22,Staff!A:B,2,FALSE) -> A103675 | AA22: =VLOOKUP(O22,Staff!A:B,2,FALSE) -> #N/A | AB22: =VLOOKUP(I22,Zone!$A$2:$B$101,2,FALSE) -> PUNGGOL | AC22: =VLOOKUP(J22,LocationGroup!$A$2:$B$35,2,FALSE) -> #N/A | AD22: =VLOOKUP(K22,Location!A:B,2,FALSE) -> #N/A | AE22: =VLOOKUP(L22,Location!A:B,2,FALSE) -> #N/A
A23: SBE2112 | B23: Lecture | C23: 1 | D23: L1 | H23: 110 | I23: PUNGGOL | N23: NADARAJAN SIVAKUMAR | P23: 9,11 | S23: 1 | T23: SBE2112-2520-ENG-UGRD-PU-LEC/L1 | U23: =VLOOKUP(A23,'Course Code'!A:D,3,FALSE) -> SBE2112-2520-ENG-UGRD-PU | V23: =VLOOKUP(U23,'Course Code'!C:D, 2, FALSE) -> 2520 | W23: =VLOOKUP(B23,'Class Type'!$A$2:$B$25,2,FALSE) -> LEC | X23: 6 | Y23: =VLOOKUP(F23,StaffGroup!$A$2:$B$35,2,FALSE) -> #N/A | Z23: =VLOOKUP(N23,Staff!A:B,2,FALSE) -> A103675 | AA23: =VLOOKUP(O23,Staff!A:B,2,FALSE) -> #N/A | AB23: =VLOOKUP(I23,Zone!$A$2:$B$101,2,FALSE) -> PUNGGOL | AC23: =VLOOKUP(J23,LocationGroup!$A$2:$B$35,2,FALSE) -> #N/A | AD23: =VLOOKUP(K23,Location!A:B,2,FALSE) -> #N/A | AE23: =VLOOKUP(L23,Location!A:B,2,FALSE) -> #N/A
A24: SBE2112 | B24: Tutorial | C24: 1 | D24: T1 | H24: 55 | I24: PUNGGOL | N24: LEE KWEE HIONG | P24: 1,2,3,4,5,6 | Q24: A0 | S24: 1 | T24: SBE2112-2520-ENG-UGRD-PU-TUT/T1 | U24: =VLOOKUP(A24,'Course Code'!A:D,3,FALSE) -> SBE2112-2520-ENG-UGRD-PU | V24: =VLOOKUP(U24,'Course Code'!C:D, 2, FALSE) -> 2520 | W24: =VLOOKUP(B24,'Class Type'!$A$2:$B$25,2,FALSE) -> TUT | X24: 4 | Y24: =VLOOKUP(F24,StaffGroup!$A$2:$B$35,2,FALSE) -> #N/A | Z24: =VLOOKUP(N24,Staff!A:B,2,FALSE) -> A88165 | AA24: =VLOOKUP(O24,Staff!A:B,2,FALSE) -> #N/A | AB24: =VLOOKUP(I24,Zone!$A$2:$B$101,2,FALSE) -> PUNGGOL | AC24: =VLOOKUP(J24,LocationGroup!$A$2:$B$35,2,FALSE) -> #N/A | AD24: =VLOOKUP(K24,Location!A:B,2,FALSE) -> #N/A | AE24: =VLOOKUP(L24,Location!A:B,2,FALSE) -> #N/A
A25: SBE2112 | B25: Tutorial | C25: 1 | D25: T2 | H25: 55 | I25: PUNGGOL | N25: LEE KWEE HIONG | P25: 1,2,3,4,5,6 | Q25: A0 | S25: 1 | T25: SBE2112-2520-ENG-UGRD-PU-TUT/T2 | U25: =VLOOKUP(A25,'Course Code'!A:D,3,FALSE) -> SBE2112-2520-ENG-UGRD-PU | V25: =VLOOKUP(U25,'Course Code'!C:D, 2, FALSE) -> 2520 | W25: =VLOOKUP(B25,'Class Type'!$A$2:$B$25,2,FALSE) -> TUT | X25: 4 | Y25: =VLOOKUP(F25,StaffGroup!$A$2:$B$35,2,FALSE) -> #N/A | Z25: =VLOOKUP(N25,Staff!A:B,2,FALSE) -> A88165 | AA25: =VLOOKUP(O25,Staff!A:B,2,FALSE) -> #N/A | AB25: =VLOOKUP(I25,Zone!$A$2:$B$101,2,FALSE) -> PUNGGOL | AC25: =VLOOKUP(J25,LocationGroup!$A$2:$B$35,2,FALSE) -> #N/A | AD25: =VLOOKUP(K25,Location!A:B,2,FALSE) -> #N/A | AE25: =VLOOKUP(L25,Location!A:B,2,FALSE) -> #N/A
A26: SBE2112 | B26: Tutorial | C26: 2 | D26: T1 | H26: 55 | I26: PUNGGOL | N26: NADARAJAN SIVAKUMAR | P26: 8,9,10,11,12,13 | Q26: A0 | S26: 1 | T26: SBE2112-2520-ENG-UGRD-PU-TUT2/T1 | U26: =VLOOKUP(A26,'Course Code'!A:D,3,FALSE) -> SBE2112-2520-ENG-UGRD-PU | V26: =VLOOKUP(U26,'Course Code'!C:D, 2, FALSE) -> 2520 | W26: =VLOOKUP(B26,'Class Type'!$A$2:$B$25,2,FALSE) -> TUT | X26: 4 | Y26: =VLOOKUP(F26,StaffGroup!$A$2:$B$35,2,FALSE) -> #N/A | Z26: =VLOOKUP(N26,Staff!A:B,2,FALSE) -> A103675 | AA26: =VLOOKUP(O26,Staff!A:B,2,FALSE) -> #N/A | AB26: =VLOOKUP(I26,Zone!$A$2:$B$101,2,FALSE) -> PUNGGOL | AC26: =VLOOKUP(J26,LocationGroup!$A$2:$B$35,2,FALSE) -> #N/A | AD26: =VLOOKUP(K26,Location!A:B,2,FALSE) -> #N/A | AE26: =VLOOKUP(L26,Location!A:B,2,FALSE) -> #N/A
A27: SBE2112 | B27: Tutorial | C27: 2 | D27: T2 | H27: 55 | I27: PUNGGOL | N27: NADARAJAN SIVAKUMAR | P27: 8,9,10,11,12,13 | Q27: A0 | S27: 1 | T27: SBE2112-2520-ENG-UGRD-PU-TUT2/T2 | U27: =VLOOKUP(A27,'Course Code'!A:D,3,FALSE) -> SBE2112-2520-ENG-UGRD-PU | V27: =VLOOKUP(U27,'Course Code'!C:D, 2, FALSE) -> 2520 | W27: =VLOOKUP(B27,'Class Type'!$A$2:$B$25,2,FALSE) -> TUT | X27: 4 | Y27: =VLOOKUP(F27,StaffGroup!$A$2:$B$35,2,FALSE) -> #N/A | Z27: =VLOOKUP(N27,Staff!A:B,2,FALSE) -> A103675 | AA27: =VLOOKUP(O27,Staff!A:B,2,FALSE) -> #N/A | AB27: =VLOOKUP(I27,Zone!$A$2:$B$101,2,FALSE) -> PUNGGOL | AC27: =VLOOKUP(J27,LocationGroup!$A$2:$B$35,2,FALSE) -> #N/A | AD27: =VLOOKUP(K27,Location!A:B,2,FALSE) -> #N/A | AE27: =VLOOKUP(L27,Location!A:B,2,FALSE) -> #N/A
A28: SBE2112 | B28: Quiz | C28: 1 | D28: Q1 | H28: 110 | I28: PUNGGOL | N28: LEE KWEE HIONG | P28: 6 | R28: w ESE2103 | S28: 1 | T28: SBE2112-2520-ENG-UGRD-PU-QUZ/Q1 | U28: =VLOOKUP(A28,'Course Code'!A:D,3,FALSE) -> SBE2112-2520-ENG-UGRD-PU | V28: =VLOOKUP(U28,'Course Code'!C:D, 2, FALSE) -> 2520 | W28: =VLOOKUP(B28,'Class Type'!$A$2:$B$25,2,FALSE) -> QUZ | X28: 4 | Y28: =VLOOKUP(F28,StaffGroup!$A$2:$B$35,2,FALSE) -> #N/A | Z28: =VLOOKUP(N28,Staff!A:B,2,FALSE) -> A88165 | AA28: =VLOOKUP(O28,Staff!A:B,2,FALSE) -> #N/A | AB28: =VLOOKUP(I28,Zone!$A$2:$B$101,2,FALSE) -> PUNGGOL | AC28: =VLOOKUP(J28,LocationGroup!$A$2:$B$35,2,FALSE) -> #N/A | AD28: =VLOOKUP(K28,Location!A:B,2,FALSE) -> #N/A | AE28: =VLOOKUP(L28,Location!A:B,2,FALSE) -> #N/A
A29: SBE2112 | B29: Quiz | C29: 2 | D29: Q1 | H29: 110 | I29: PUNGGOL | N29: NADARAJAN SIVAKUMAR | P29: 13 | S29: 1 | T29: SBE2112-2520-ENG-UGRD-PU-QUZ2/Q1 | U29: =VLOOKUP(A29,'Course Code'!A:D,3,FALSE) -> SBE2112-2520-ENG-UGRD-PU | V29: =VLOOKUP(U29,'Course Code'!C:D, 2, FALSE) -> 2520 | W29: =VLOOKUP(B29,'Class Type'!$A$2:$B$25,2,FALSE) -> QUZ | X29: 4 | Y29: =VLOOKUP(F29,StaffGroup!$A$2:$B$35,2,FALSE) -> #N/A | Z29: =VLOOKUP(N29,Staff!A:B,2,FALSE) -> A103675 | AA29: =VLOOKUP(O29,Staff!A:B,2,FALSE) -> #N/A | AB29: =VLOOKUP(I29,Zone!$A$2:$B$101,2,FALSE) -> PUNGGOL | AC29: =VLOOKUP(J29,LocationGroup!$A$2:$B$35,2,FALSE) -> #N/A | AD29: =VLOOKUP(K29,Location!A:B,2,FALSE) -> #N/A | AE29: =VLOOKUP(L29,Location!A:B,2,FALSE) -> #N/A
A30: SBE3113A | B30: Workshop | C30: 1 | D30: W1 | E30: Wed | F30: 1500 | H30: 110 | N30: ZHANG WEILI | P30: 1 | S30: 1 | T30: SBE3113A-2520-ENG-UGRD-PU-WOR/W1 | U30: =VLOOKUP(A30,'Course Code'!A:D,3,FALSE) -> SBE3113A-2520-ENG-UGRD-PU | V30: =VLOOKUP(U30,'Course Code'!C:D, 2, FALSE) -> 2520 | W30: =VLOOKUP(B30,'Class Type'!$A$2:$B$25,2,FALSE) -> WOR | X30: 6 | Y30: =VLOOKUP(F30,StaffGroup!$A$2:$B$35,2,FALSE) -> #N/A | Z30: =VLOOKUP(N30,Staff!A:B,2,FALSE) -> A101475 | AA30: =VLOOKUP(O30,Staff!A:B,2,FALSE) -> #N/A | AB30: =VLOOKUP(I30,Zone!$A$2:$B$101,2,FALSE) -> #N/A | AC30: =VLOOKUP(J30,LocationGroup!$A$2:$B$35,2,FALSE) -> #N/A | AD30: =VLOOKUP(K30,Location!A:B,2,FALSE) -> #N/A | AE30: =VLOOKUP(L30,Location!A:B,2,FALSE) -> #N/A
U31: =VLOOKUP(A31,'Course Code'!A:D,3,FALSE) -> #N/A | V31: =VLOOKUP(U31,'Course Code'!C:D, 2, FALSE) -> #N/A | W31: =VLOOKUP(B31,'Class Type'!$A$2:$B$25,2,FALSE) -> #N/A | X31: =ROUNDUP((G31-F31)/100*2,0) -> 0 | Y31: =VLOOKUP(F31,StaffGroup!$A$2:$B$35,2,FALSE) -> #N/A | Z31: =VLOOKUP(N31,Staff!A:B,2,FALSE) -> #N/A | AA31: =VLOOKUP(O31,Staff!A:B,2,FALSE) -> #N/A | AB31: =VLOOKUP(I31,Zone!$A$2:$B$101,2,FALSE) -> #N/A | AC31: =VLOOKUP(J31,LocationGroup!$A$2:$B$35,2,FALSE) -> #N/A | AD31: =VLOOKUP(K31,Location!A:B,2,FALSE) -> #N/A | AE31: =VLOOKUP(L31,Location!A:B,2,FALSE) -> #N/A
U32: =VLOOKUP(A32,'Course Code'!A:D,3,FALSE) -> #N/A | V32: =VLOOKUP(U32,'Course Code'!C:D, 2, FALSE) -> #N/A | W32: =VLOOKUP(B32,'Class Type'!$A$2:$B$25,2,FALSE) -> #N/A | X32: =ROUNDUP((G32-F32)/100*2,0) -> 0 | Y32: =VLOOKUP(F32,StaffGroup!$A$2:$B$35,2,FALSE) -> #N/A | Z32: =VLOOKUP(N32,Staff!A:B,2,FALSE) -> #N/A | AA32: =VLOOKUP(O32,Staff!A:B,2,FALSE) -> #N/A | AB32: =VLOOKUP(I32,Zone!$A$2:$B$101,2,FALSE) -> #N/A | AC32: =VLOOKUP(J32,LocationGroup!$A$2:$B$35,2,FALSE) -> #N/A | AD32: =VLOOKUP(K32,Location!A:B,2,FALSE) -> #N/A | AE32: =VLOOKUP(L32,Location!A:B,2,FALSE) -> #N/A
U33: =VLOOKUP(A33,'Course Code'!A:D,3,FALSE) -> #N/A | V33: =VLOOKUP(U33,'Course Code'!C:D, 2, FALSE) -> #N/A | W33: =VLOOKUP(B33,'Class Type'!$A$2:$B$25,2,FALSE) -> #N/A | X33: =ROUNDUP((G33-F33)/100*2,0) -> 0 | Y33: =VLOOKUP(F33,StaffGroup!$A$2:$B$35,2,FALSE) -> #N/A | Z33: =VLOOKUP(N33,Staff!A:B,2,FALSE) -> #N/A | AA33: =VLOOKUP(O33,Staff!A:B,2,FALSE) -> #N/A | AB33: =VLOOKUP(I33,Zone!$A$2:$B$101,2,FALSE) -> #N/A | AC33: =VLOOKUP(J33,LocationGroup!$A$2:$B$35,2,FALSE) -> #N/A | AD33: =VLOOKUP(K33,Location!A:B,2,FALSE) -> #N/A | AE33: =VLOOKUP(L33,Location!A:B,2,FALSE) -> #N/A
U34: =VLOOKUP(A34,'Course Code'!A:D,3,FALSE) -> #N/A | V34: =VLOOKUP(U34,'Course Code'!C:D, 2, FALSE) -> #N/A | W34: =VLOOKUP(B34,'Class Type'!$A$2:$B$25,2,FALSE) -> #N/A | X34: =ROUNDUP((G34-F34)/100*2,0) -> 0 | Y34: =VLOOKUP(F34,StaffGroup!$A$2:$B$35,2,FALSE) -> #N/A | Z34: =VLOOKUP(N34,Staff!A:B,2,FALSE) -> #N/A | AA34: =VLOOKUP(O34,Staff!A:B,2,FALSE) -> #N/A | AB34: =VLOOKUP(I34,Zone!$A$2:$B$101,2,FALSE) -> #N/A | AC34: =VLOOKUP(J34,LocationGroup!$A$2:$B$35,2,FALSE) -> #N/A | AD34: =VLOOKUP(K34,Location!A:B,2,FALSE) -> #N/A | AE34: =VLOOKUP(L34,Location!A:B,2,FALSE) -> #N/A
U35: =VLOOKUP(A35,'Course Code'!A:D,3,FALSE) -> #N/A | V35: =VLOOKUP(U35,'Course Code'!C:D, 2, FALSE) -> #N/A | W35: =VLOOKUP(B35,'Class Type'!$A$2:$B$25,2,FALSE) -> #N/A | X35: =ROUNDUP((G35-F35)/100*2,0) -> 0 | Y35: =VLOOKUP(F35,StaffGroup!$A$2:$B$35,2,FALSE) -> #N/A | Z35: =VLOOKUP(N35,Staff!A:B,2,FALSE) -> #N/A | AA35: =VLOOKUP(O35,Staff!A:B,2,FALSE) -> #N/A | AB35: =VLOOKUP(I35,Zone!$A$2:$B$101,2,FALSE) -> #N/A | AC35: =VLOOKUP(J35,LocationGroup!$A$2:$B$35,2,FALSE) -> #N/A | AD35: =VLOOKUP(K35,Location!A:B,2,FALSE) -> #N/A | AE35: =VLOOKUP(L35,Location!A:B,2,FALSE) -> #N/A
U36: =VLOOKUP(A36,'Course Code'!A:D,3,FALSE) -> #N/A | V36: =VLOOKUP(U36,'Course Code'!C:D, 2, FALSE) -> #N/A | W36: =VLOOKUP(B36,'Class Type'!$A$2:$B$25,2,FALSE) -> #N/A | X36: =ROUNDUP((G36-F36)/100*2,0) -> 0 | Y36: =VLOOKUP(F36,StaffGroup!$A$2:$B$35,2,FALSE) -> #N/A | Z36: =VLOOKUP(N36,Staff!A:B,2,FALSE) -> #N/A | AA36: =VLOOKUP(O36,Staff!A:B,2,FALSE) -> #N/A | AB36: =VLOOKUP(I36,Zone!$A$2:$B$101,2,FALSE) -> #N/A | AC36: =VLOOKUP(J36,LocationGroup!$A$2:$B$35,2,FALSE) -> #N/A | AD36: =VLOOKUP(K36,Location!A:B,2,FALSE) -> #N/A | AE36: =VLOOKUP(L36,Location!A:B,2,FALSE) -> #N/A
U37: =VLOOKUP(A37,'Course Code'!A:D,3,FALSE) -> #N/A | V37: =VLOOKUP(U37,'Course Code'!C:D, 2, FALSE) -> #N/A | W37: =VLOOKUP(B37,'Class Type'!$A$2:$B$25,2,FALSE) -> #N/A | X37: =ROUNDUP((G37-F37)/100*2,0) -> 0 | Y37: =VLOOKUP(F37,StaffGroup!$A$2:$B$35,2,FALSE) -> #N/A | Z37: =VLOOKUP(N37,Staff!A:B,2,FALSE) -> #N/A | AA37: =VLOOKUP(O37,Staff!A:B,2,FALSE) -> #N/A | AB37: =VLOOKUP(I37,Zone!$A$2:$B$101,2,FALSE) -> #N/A | AC37: =VLOOKUP(J37,LocationGroup!$A$2:$B$35,2,FALSE) -> #N/A | AD37: =VLOOKUP(K37,Location!A:B,2,FALSE) -> #N/A | AE37: =VLOOKUP(L37,Location!A:B,2,FALSE) -> #N/A
U38: =VLOOKUP(A38,'Course Code'!A:D,3,FALSE) -> #N/A | V38: =VLOOKUP(U38,'Course Code'!C:D, 2, FALSE) -> #N/A | W38: =VLOOKUP(B38,'Class Type'!$A$2:$B$25,2,FALSE) -> #N/A | X38: =ROUNDUP((G38-F38)/100*2,0) -> 0 | Y38: =VLOOKUP(F38,StaffGroup!$A$2:$B$35,2,FALSE) -> #N/A | Z38: =VLOOKUP(N38,Staff!A:B,2,FALSE) -> #N/A | AA38: =VLOOKUP(O38,Staff!A:B,2,FALSE) -> #N/A | AB38: =VLOOKUP(I38,Zone!$A$2:$B$101,2,FALSE) -> #N/A | AC38: =VLOOKUP(J38,LocationGroup!$A$2:$B$35,2,FALSE) -> #N/A | AD38: =VLOOKUP(K38,Location!A:B,2,FALSE) -> #N/A | AE38: =VLOOKUP(L38,Location!A:B,2,FALSE) -> #N/A
U39: =VLOOKUP(A39,'Course Code'!A:D,3,FALSE) -> #N/A | V39: =VLOOKUP(U39,'Course Code'!C:D, 2, FALSE) -> #N/A | W39: =VLOOKUP(B39,'Class Type'!$A$2:$B$25,2,FALSE) -> #N/A | X39: =ROUNDUP((G39-F39)/100*2,0) -> 0 | Y39: =VLOOKUP(F39,StaffGroup!$A$2:$B$35,2,FALSE) -> #N/A | Z39: =VLOOKUP(N39,Staff!A:B,2,FALSE) -> #N/A | AA39: =VLOOKUP(O39,Staff!A:B,2,FALSE) -> #N/A | AB39: =VLOOKUP(I39,Zone!$A$2:$B$101,2,FALSE) -> #N/A | AC39: =VLOOKUP(J39,LocationGroup!$A$2:$B$35,2,FALSE) -> #N/A | AD39: =VLOOKUP(K39,Location!A:B,2,FALSE) -> #N/A | AE39: =VLOOKUP(L39,Location!A:B,2,FALSE) -> #N/A
U40: =VLOOKUP(A40,'Course Code'!A:D,3,FALSE) -> #N/A | V40: =VLOOKUP(U40,'Course Code'!C:D, 2, FALSE) -> #N/A | W40: =VLOOKUP(B40,'Class Type'!$A$2:$B$25,2,FALSE) -> #N/A | X40: =ROUNDUP((G40-F40)/100*2,0) -> 0 | Y40: =VLOOKUP(F40,StaffGroup!$A$2:$B$35,2,FALSE) -> #N/A | Z40: =VLOOKUP(N40,Staff!A:B,2,FALSE) -> #N/A | AA40: =VLOOKUP(O40,Staff!A:B,2,FALSE) -> #N/A | AB40: =VLOOKUP(I40,Zone!$A$2:$B$101,2,FALSE) -> #N/A | AC40: =VLOOKUP(J40,LocationGroup!$A$2:$B$35,2,FALSE) -> #N/A | AD40: =VLOOKUP(K40,Location!A:B,2,FALSE) -> #N/A | AE40: =VLOOKUP(L40,Location!A:B,2,FALSE) -> #N/A
...

Sheet Course Code
A1: Module Code | B1: Term | C1: Host Key | D1: Term
A2: AAI1001 | B2: 2520 | C2: AAI1001-2520-ICT-UGRD-PU | D2: 2520
A3: AAI2002 | B3: 2520 | C3: AAI2002-2520-ICT-UGRD-PU | D3: 2520
A4: AAI3008 | B4: 2520 | C4: AAI3008-2520-ICT-UGRD-PU | D4: 2520
A5: AAI4001 | B5: 2520 | C5: AAI4001-2520-ICT-UGRD-PU | D5: 2520
A6: AAI4002A | B6: 2520 | C6: AAI4002A-2520-ICT-UGRD-PU | D6: 2520
A7: AAI4002B | B7: 2520 | C7: AAI4002B-2520-ICT-UGRD-PU | D7: 2520
A8: ACC1023 | B8: 2520 | C8: ACC1023-2520-BCD-UGRD-PU | D8: 2520
A9: ACC1024 | B9: 2520 | C9: ACC1024-2520-BCD-UGRD-PU | D9: 2520
A10: ACC1025 | B10: 2520 | C10: ACC1025-2520-BCD-UGRD-PU | D10: 2520
A11: ACC1026 | B11: 2520 | C11: ACC1026-2520-BCD-UGRD-PU | D11: 2520
A12: ACC3001A | B12: 2520 | C12: ACC3001A-2520-BCD-UGRD-PU | D12: 2520
A13: ACC3001B | B13: 2520 | C13: ACC3001B-2520-BCD-UGRD-PU | D13: 2520
... A476: UXG4990 | B476: 2520 | C476: UXG4990-2520-ICT-UDGP-PU | D476: 2520

Sheet Location
A1: Name | B1: Host Key | C1: Capacity | D1: Department | E1: Zone | F1: Shared With | G1: Shared With All | H1: Primary Suitabilities | I1: Other Suitabilities | J1: Contract Periods | K1: Maximum Periods | L1: Constraint Profiles | M1: Cost Band
A2: CEFT External Venue | B2: CEFT External Venue | C2: 200 | D2: CEFT | E2: DOVER | F2: All | G2: Checked | H2: Teaching Facilities | J2: 196 | K2: 196 | M2: None
A3: DV-AP-LT1A | B3: DV-AP-LT1A | C3: 49 | D3: AP-DV | E3: DV-ACAD PLAZA-LEVEL 1 | F3: All | G3: Checked | H3: DV-Lecture-Recording, Lecture Theatre, LT-DV, LT-DV-AP, Room with Lecture Recording, Teaching Facilities | J3: 196 | K3: 196 | M3: None
A4: DV-AP-LT1B | B4: DV-AP-LT1B | C4: 49 | D4: AP-DV | E4: DV-ACAD PLAZA-LEVEL 1 | F4: All | G4: Checked | H4: DV-Lecture-Recording, Lecture Theatre, LT-DV, LT-DV-AP, Room with Lecture Recording, Teaching Facilities | J4: 196 | K4: 196 | M4: None
A5: DV-AP-LT2A | B5: DV-AP-LT2A | C5: 43 | D5: AP-DV | E5: DV-ACAD PLAZA-LEVEL 2 | F5: All | G5: Checked | H5: DV-Lecture-Recording, Lecture Theatre, LT-DV, LT-DV-AP, Room with Lecture Recording, Teaching Facilities | J5: 196 | K5: 196 | M5: None
A6: DV-AP-LT2B | B6: DV-AP-LT2B | C6: 44 | D6: AP-DV | E6: DV-ACAD PLAZA-LEVEL 2 | F6: All | G6: Checked | H6: DV-Lecture-Recording, Lecture Theatre, LT-DV, LT-DV-AP, Room with Lecture Recording, Teaching Facilities | J6: 196 | K6: 196 | M6: None
A7: DV-AP-LT2C | B7: DV-AP-LT2C | C7: 36 | D7: AP-DV | E7: DV-ACAD PLAZA-LEVEL 2 | F7: All | G7: Checked | H7: DV-Lecture-Recording, Lecture Theatre, LT-DV, LT-DV-AP, Room with Lecture Recording, Teaching Facilities | J7: 196 | K7: 196 | M7: None
A8: DV-AP-LT2D | B8: DV-AP-LT2D | C8: 26 | D8: AP-DV | E8: DV-ACAD PLAZA-LEVEL 2 | F8: All | G8: Checked | H8: DV-Lecture-Recording, Lecture Theatre, LT-DV, LT-DV-AP, Room with Lecture Recording, Teaching Facilities | J8: 196 | K8: 196 | M8: None
A9: DV-AP-LT2E | B9: DV-AP-LT2E | C9: 20 | D9: AP-DV | E9: DV-ACAD PLAZA-LEVEL 2 | F9: All | G9: Checked | H9: DV-Lecture-Recording, Lecture Theatre, LT-DV, LT-DV-AP, Room with Lecture Recording, Teaching Facilities | J9: 196 | K9: 196 | M9: None
A10: DV-AP-SR1B | B10: DV-AP-SR1B | C10: 20 | D10: POD-DV | E10: DV-ACAD PLAZA-LEVEL 1 | F10: All | G10: Checked | H10: Laboratory, Seminar Room, SR-DV, SR-DV-AP, Teaching Facilities | J10: 196 | K10: 196 | M10: None
A11: DV-AP-SR1D | B11: DV-AP-SR1D | C11: 20 | D11: POD-DV | E11: DV-ACAD PLAZA-LEVEL 1 | F11: All | G11: Checked | H11: Laboratory, Seminar Room, SR-DV, SR-DV-AP, Teaching Facilities | J11: 196 | K11: 196 | M11: None
A12: DV-AP-SR1E | B12: DV-AP-SR1E | C12: 20 | D12: POD-DV | E12: DV-ACAD PLAZA-LEVEL 1 | F12: All | G12: Checked | H12: Laboratory, Seminar Room, SR-DV, SR-DV-AP, Teaching Facilities | J12: 196 | K12: 196 | M12: None
A13: DV-AP-SR1H | B13: DV-AP-SR1H | C13: 25 | D13: AP-DV | E13: DV-ACAD PLAZA-LEVEL 1 | F13: All | G13: Checked | H13: Laboratory, Teaching Facilities | J13: 196 | K13: 196 | M13: None
... A193: NYP-L7 SR7E | B193: NYP-SR7E | C193: 50 | D193: AP-NYP | E193: NYP-LEVEL 7 | F193: All | G193: Checked | H193: NYP-Lecture-Recording, Room with Lecture Recording, Seminar Room, SR-NYP, Teaching Facilities | J193: 196 | K193: 196 | M193: None
A194: Online | B194: Online | C194: 9000 | D194: AP-DV | E194: SIT | F194: All | G194: Checked | J194: 196 | K194: 196 | M194: None
A195: RP-LT1A | B195: RP-LT1A | C195: 34 | D195: AP-RP | E195: RP-LEVEL 1 | F195: All | G195: Checked | H195: Lecture Theatre, LT-RP, Room with Lecture Recording, RP-Lecture-Recording, Teaching Facilities | J195: 196 | K195: 196 | M195: None
A196: RP-LT1B | B196: RP-LT1B | C196: 34 | D196: AP-RP | E196: RP-LEVEL 1 | F196: All | G196: Checked | H196: Lecture Theatre, LT-RP, Room with Lecture Recording, RP-Lecture-Recording, Teaching Facilities | J196: 196 | K196: 196 | M196: None
A197: RP-LT6A | B197: RP-LT6A | C197: 18 | D197: AP-RP | E197: RP-LEVEL 6 | F197: All | G197: Checked | H197: Lecture Theatre, LT-RP, Room with Lecture Recording, RP-Lecture-Recording, Teaching Facilities | J197: 196 | K197: 196 | M197: None
A198: RP-LT7A | B198: RP-LT7A | C198: 18 | D198: AP-RP | E198: RP-LEVEL 7 | F198: All | G198: Checked | H198: Lecture Theatre, LT-RP, Room with Lecture Recording, RP-Lecture-Recording, Teaching Facilities | J198: 196 | K198: 196 | M198: None
A199: RP-LT8A | B199: RP-LT8A | C199: 18 | D199: AP-RP | E199: RP-LEVEL 8 | F199: All | G199: Checked | H199: Lecture Theatre, LT-RP, Room with Lecture Recording, RP-Lecture-Recording, Teaching Facilities | J199: 196 | K199: 196 | M199: None
A200: RP-SR1A | B200: RP-SR1A | C200: 50 | D200: AP-RP | E200: RP-LEVEL 1 | F200: All | G200: Checked | H200: Laboratory, Seminar Room, SR-RP, Teaching Facilities | J200: 196 | K200: 196 | M200: None
A201: RP-SR5D1 | B201: RP-SR5D1 | C201: 49 | D201: AP-RP | E201: RP-LEVEL 5 | F201: All | G201: Checked | H201: Seminar Room, SR-RP, Teaching Facilities | J201: 196 | K201: 196 | M201: None
A202: RP-SR5D2 | B202: RP-SR5D2 | C202: 47 | D202: AP-RP | E202: RP-LEVEL 5 | F202: All | G202: Checked | H202: Seminar Room, SR-RP, Teaching Facilities | J202: 196 | K202: 196 | M202: None
A203: RP-SR6A | B203: RP-SR6A | C203: 18 | D203: AP-RP | E203: RP-LEVEL 6 | F203: All | G203: Checked | H203: Room with Lecture Recording, RP-Lecture-Recording, Seminar Room, SR-RP, Teaching Facilities | J203: 196 | K203: 196 | M203: None
A204: RP-SR6B | B204: RP-SR6B | C204: 20 | D204: AP-RP | E204: RP-LEVEL 6 | F204: All | G204: Checked | H204: Room with Lecture Recording, RP-Lecture-Recording, Seminar Room, SR-RP, Teaching Facilities | J204: 196 | K204: 196 | M204: None
A205: RP-SR6C | B205: RP-SR6C | C205: 18 | D205: AP-RP | E205: RP-LEVEL 6 | F205: All | G205: Checked | H205: Room with Lecture Recording, RP-Lecture-Recording, Seminar Room, SR-RP, Teaching Facilities | J205: 196 | K205: 196 | M205: None
A206: RP-SR6D | B206: RP-SR6D | C206: 18 | D206: AP-RP | E206: RP-LEVEL 6 | F206: All | G206: Checked | H206: Room with Lecture Recording, RP-Lecture-Recording, Seminar Room, SR-RP, Teaching Facilities | J206: 196 | K206: 196 | M206: None
... A273: SP-SR6F | B273: SP-SR6F | C273: 10 | D273: AP-SP | E273: SP-LEVEL 6 | F273: All | G273: Checked | H273: Seminar Room, SR-SP, Teaching Facilities | J273: 196 | K273: 196 | M273: None
A274: *Temp Venue | B274: Temp Venue001 | C274: 999 | D274: AP-DV | E274: SIT | F274: All | G274: Checked | J274: 196 | K274: 196 | M274: None
A275: TP-LT1A | B275: TP-LT1A | C275: 49 | D275: AP-TP | E275: TP-LEVEL 1 | F275: All | G275: Checked | H275: Lecture Theatre, LT-TP, Room with Lecture Recording, Teaching Facilities, TP-Lecture-Recording | J275: 196 | K275: 196 | M275: None
A276: TP-LT1B | B276: TP-LT1B | C276: 25 | D276: AP-TP | E276: TP-LEVEL 1 | F276: All | G276: Checked | H276: Lecture Theatre, LT-TP, Room with Lecture Recording, Teaching Facilities, TP-Lecture-Recording | J276: 196 | K276: 196 | M276: None
A277: TP-LT2A | B277: TP-LT2A | C277: 19 | D277: AP-TP | E277: TP-LEVEL 2 | F277: All | G277: Checked | H277: Lecture Theatre, LT-TP, Room with Lecture Recording, Teaching Facilities, TP-Lecture-Recording | J277: 196 | K277: 196 | M277: None
A278: TP-LT5A | B278: TP-LT5A | C278: 49 | D278: AP-TP | E278: TP-LEVEL 5 | F278: All | G278: Checked | H278: Lecture Theatre, LT-TP, Room with Lecture Recording, Teaching Facilities, TP-Lecture-Recording | J278: 196 | K278: 196 | M278: None
A279: TP-SR1A | B279: TP-SR1A | C279: 24 | D279: AP-TP | E279: TP-LEVEL 1 | F279: All | G279: Checked | H279: Room with Lecture Recording, Seminar Room, SR-TP, Teaching Facilities, TP-Lecture-Recording | J279: 196 | K279: 196 | M279: None
A280: TP-SR2A | B280: TP-SR2A | C280: 24 | D280: AP-TP | E280: TP-LEVEL 2 | F280: All | G280: Checked | H280: Room with Lecture Recording, Seminar Room, SR-TP, Teaching Facilities, TP-Lecture-Recording | J280: 196 | K280: 196 | M280: None
A281: TP-SR2B | B281: TP-SR2B | C281: 24 | D281: AP-TP | E281: TP-LEVEL 2 | F281: All | G281: Checked | H281: Room with Lecture Recording, Seminar Room, SR-TP, Teaching Facilities, TP-Lecture-Recording | J281: 196 | K281: 196 | M281: None
A282: TP-SR2C | B282: TP-SR2C | C282: 25 | D282: AP-TP | E282: TP-LEVEL 2 | F282: All | G282: Checked | H282: Room with Lecture Recording, Seminar Room, SR-TP, Teaching Facilities, TP-Lecture-Recording | J282: 196 | K282: 196 | M282: None
A283: TP-SR2D | B283: TP-SR2D | C283: 22 | D283: AP-TP | E283: TP-LEVEL 2 | F283: All | G283: Checked | H283: Room with Lecture Recording, Seminar Room, SR-TP, Teaching Facilities, TP-Lecture-Recording | J283: 196 | K283: 196 | M283: None
A284: TP-SR2E | B284: TP-SR2E | C284: 24 | D284: AP-TP | E284: TP-LEVEL 2 | F284: All | G284: Checked | H284: Room with Lecture Recording, Seminar Room, SR-TP, Teaching Facilities, TP-Lecture-Recording | J284: 196 | K284: 196 | M284: None
A285: TP-SR3A | B285: TP-SR3A | C285: 24 | D285: AP-TP | E285: TP-LEVEL 3 | F285: All | G285: Checked | H285: Seminar Room, SR-TP, Teaching Facilities | J285: 196 | K285: 196 | M285: None
...

Sheet Staff
A1: Name | B1: Host Key
A2: 'AFIFAH BINTE ABDUL RAHMAN . | B2: A102199
A3: DEVENNEY KATE ELIZABET . | B3: G19032
A4: JESMOND HONG . | B4: G13034
A5: JOSEPH GREENER . | B5: G20014
A6: KATE MARIE MACNAMARA . | B6: G19040
A7: LYNN ONG . | B7: G21153
A8: MOHAMMAD SHIHABUL HAQUE . | B8: G21142
A9: PABLO LEANDRO CIOCCHINI . | B9: G20005
A10: SLAWOMIR GRZEGORZ WLODKOWSKI . | B10: G21133
A11: WEE FONG CHI . | B11: H52298
A12: YANNICK VINCENT GERBER . | B12: G21147
... A2295: ZUO JIAN | B2295: A100831

Sheet Group
A1: List
A2: All
A3: L1
A4: L2
A5: L3
A6: L4
A7: L5
A8: L6
A9: L7
A10: L8
A11: L9
A12: L10
... A81: Q18

Sheet LocationGroup
A1: Name | B1: Host Key
A2: Auditorium-DV | B2: Auditorium-DV
A3: LT-All | B3: Lecture Theatre
A4: LT-DV | B4: LT-DV
A5: LT-DV-AP | B5: LT-DV-AP
A6: LT-DV-USC | B6: LT-DV-USC
A7: LT-NP | B7: LT-NP
A8: LT-NYP | B8: LT-NYP
A9: LT-RP | B9: LT-RP
A10: LT-SP | B10: LT-SP
A11: LT-TP | B11: LT-TP
A12: SR-All | B12: SR-All
... A21: SR-TP | B21: SR-TP

Sheet Zone
A1: Name | B1: Host Key
A2: DV | B2: DV | C2: [Select Department] | E2: SIT
A3: DV-ACAD PLAZA | B3: DV-ACAD PLAZA | C3: [Select Department] | E3: DV
A4: DV-ACAD PLAZA-B1 | B4: DV-ACAD PLAZA-B1 | C4: [Select Department] | E4: DV-ACAD PLAZA
A5: DV-ACAD PLAZA-LEVEL 1 | B5: DV-ACAD PLAZA-LEVEL 1 | C5: [Select Department] | E5: DV-ACAD PLAZA
A6: DV-ACAD PLAZA-LEVEL 2 | B6: DV-ACAD PLAZA-LEVEL 2 | C6: [Select Department] | E6: DV-ACAD PLAZA
A7: DV-ACAD PLAZA-LEVEL 3 | B7: DV-ACAD PLAZA-LEVEL 3 | C7: [Select Department] | E7: DV-ACAD PLAZA
A8: DV-ACAD PLAZA-LEVEL 4 | B8: DV-ACAD PLAZA-LEVEL 4 | C8: [Select Department] | E8: DV-ACAD PLAZA
A9: DV-OUTDOOR | B9: DV-OUTDOOR | C9: [Select Department] | E9: DV
A10: DV-OUTDOOR-LEVEL 1 | B10: DV-OUTDOOR-LEVEL 1 | C10: [Select Department] | E10: DV-OUTDOOR
A11: DV-RECREATION CENTRE | B11: #SPLUS95EB30 | C11: [Select Department] | E11: DV
A12: DV-RECREATION CENTRE-LEVEL 1 | B12: #SPLUS8EFCD3 | C12: [Select Department] | E12: DV-RECREATION CENTRE
A13: DV-RECREATION CENTRE-LEVEL 2 | B13: #SPLUS18DE5A | C13: [Select Department] | E13: DV-RECREATION CENTRE
... A51: NYP-LEVEL 7 | B51: NYP-LEVEL 7 | C51: [Select Department] | E51: NYP
A52: PUNGGOL | B52: PUNGGOL
A53: RP | B53: RP | C53: [Select Department] | E53: SIT
A54: RP-LEVEL 1 | B54: RP-LEVEL 1 | C54: [Select Department] | E54: RP
A55: RP-LEVEL 2 | B55: RP-LEVEL 2 | C55: [Select Department] | E55: RP
A56: RP-LEVEL 5 | B56: RP-LEVEL 5 | C56: [Select Department] | E56: RP
A57: RP-LEVEL 6 | B57: RP-LEVEL 6 | C57: [Select Department] | E57: RP
A58: RP-LEVEL 7 | B58: RP-LEVEL 7 | C58: [Select Department] | E58: RP
A59: RP-LEVEL 8 | B59: RP-LEVEL 8 | C59: [Select Department] | E59: RP
A60: RP-LEVEL 9 | B60: RP-LEVEL 9 | C60: [Select Department] | E60: RP
A61: SIT | B61: SIT | C61: [Select Department] | E61: None
A62: SIT@SP LTs & SRs | B62: #SPLUSFDB04E | C62: AP-SP | E62: SP
A63: SP | B63: SP | C63: [Select Department] | E63: SIT
A64: SP-LEVEL 1 | B64: SP-LEVEL 1 | C64: [Select Department] | E64: SP
... A75: TP-LEVEL 5 | B75: TP-LEVEL 5 | C75: [Select Department] | E75: TP

Sheet Sheet4
A1: Name | B1: Host Key | C1: Description | D1: Credit Provided | E1: Department | F1: Reserved Size | G1: Total Size | H1: Real Size | I1: Named Availability | J1: Weeks | K1: Named Starts | L1: Named Usage
A2: ACC1001-2110-DSB-UGRD-DOVER | B2: ACC1001-2110-DSB-UGRD-DOVER | C2: Introduction to Financial Accounting | D2: 5 | E2: DSB | F2: 0 | G2: 0 | H2: 0 | I2: [Custom...] | J2: 23743 | K2: [Custom...] | L2: [Custom...]
A3: ACC1002-2110-DSB-UGRD-DOVER | B3: ACC1002-2110-DSB-UGRD-DOVER | C3: Introduction to Economics | D3: 5 | E3: DSB | F3: 0 | G3: 0 | H3: 0 | I3: [Custom...] | J3: 23743 | K3: [Custom...] | L3: [Custom...]
A4: ACC1003-2110-DSB-UGRD-DOVER | B4: ACC1003-2110-DSB-UGRD-DOVER | C4: Organisation and Management | D4: 5 | E4: DSB | F4: 0 | G4: 0 | H4: 0 | I4: [Custom...] | J4: 23743 | K4: [Custom...] | L4: [Custom...]
A5: ACC1004-2110-DSB-UGRD-DOVER | B5: ACC1004-2110-DSB-UGRD-DOVER | C5: Business Law | D5: 5 | E5: DSB | F5: 0 | G5: 0 | H5: 0 | I5: [Custom...] | J5: 23743 | K5: [Custom...] | L5: [Custom...]
A6: ACC1005-2110-DSB-UGRD-DOVER | B6: ACC1005-2110-DSB-UGRD-DOVER | C6: Foundations of Finance | D6: 5 | E6: DSB | F6: 0 | G6: 0 | H6: 0 | I6: [Custom...] | J6: 23743 | K6: [Custom...] | L6: [Custom...]
A7: ACC1106-2110-DSB-UGRD-DOVER | B7: ACC1106-2110-DSB-UGRD-DOVER | C7: Quantitative Analysis | D7: 5 | E7: DSB | F7: 0 | G7: 0 | H7: 0 | I7: [Custom...] | J7: 23743 | K7: [Custom...] | L7: [Custom...]
A8: ACC2001-2110-DSB-UGRD-DOVER | B8: ACC2001-2110-DSB-UGRD-DOVER | C8: Financial Accounting | D8: 5 | E8: DSB | F8: 0 | G8: 0 | H8: 0 | I8: [Custom...] | J8: 23743 | K8: [Custom...] | L8: [Custom...]
A9: ACC2002-2110-DSB-UGRD-DOVER | B9: ACC2002-2110-DSB-UGRD-DOVER | C9: Auditing | D9: 5 | E9: DSB | F9: 0 | G9: 0 | H9: 0 | I9: [Custom...] | J9: 23743 | K9: [Custom...] | L9: [Custom...]
A10: ACC2003-2110-DSB-UGRD-DOVER | B10: ACC2003-2110-DSB-UGRD-DOVER | C10: Company Law | D10: 5 | E10: DSB | F10: 0 | G10: 0 | H10: 0 | I10: [Custom...] | J10: 23743 | K10: [Custom...] | L10: [Custom...]
A11: ACC2004-2110-DSB-UGRD-DOVER | B11: ACC2004-2110-DSB-UGRD-DOVER | C11: Corporate Finance | D11: 5 | E11: DSB | F11: 0 | G11: 0 | H11: 0 | I11: [Custom...] | J11: 23743 | K11: [Custom...] | L11: [Custom...]
A12: ACC2103-2110-DSB-UGRD-DOVER | B12: ACC2103-2110-DSB-UGRD-DOVER | C12: Company and Securities Law | D12: 5 | E12: DSB | F12: 0 | G12: 0 | H12: 0 | I12: [Custom...] | J12: 23743 | K12: [Custom...] | L12: [Custom...]
A13: ACC2901-2110-DSB-UGRD-DOVER | B13: ACC2901-2110-DSB-UGRD-DOVER | C13: Value Added Programme 1 (Essentials of an Auditor) | D13: 2 | E13: DSB | F13: 0 | G13: 0 | H13: 0 | I13: [Custom...] | J13: 23743 | K13: [Custom...] | L13: [Custom...]
... A449: UXG2570-2110-ICT-UDGP-SP | B449: UXG2570-2110-ICT-UDGP-SP | C449: User Research 1 | D449: 5 | E449: ICT | F449: 0 | G449: 0 | H449: 0 | I449: [Custom...] | J449: 23743 | K449: [Custom...] | L449: [Custom...]

Sheet Sheet1
A1: Name | B1: Host Key | C1: Description | D1: Credit Provided | E1: Department | F1: Reserved Size | G1: Total Size | H1: Real Size | I1: Named Availability | J1: Weeks | K1: Named Starts | L1: Named Usage
A2: ACC1001-2110-DSB-UGRD-DOVER | B2: ACC1001-2110-DSB-UGRD-DOVER | C2: Introduction to Financial Accounting | D2: 5 | E2: DSB | F2: 0 | G2: 0 | H2: 0 | I2: [Custom...] | J2: 23743 | K2: [Custom...] | L2: [Custom...]
A3: ACC1002-2110-DSB-UGRD-DOVER | B3: ACC1002-2110-DSB-UGRD-DOVER | C3: Introduction to Economics | D3: 5 | E3: DSB | F3: 0 | G3: 0 | H3: 0 | I3: [Custom...] | J3: 23743 | K3: [Custom...] | L3: [Custom...]
A4: ACC1003-2110-DSB-UGRD-DOVER | B4: ACC1003-2110-DSB-UGRD-DOVER | C4: Organisation and Management | D4: 5 | E4: DSB | F4: 0 | G4: 0 | H4: 0 | I4: [Custom...] | J4: 23743 | K4: [Custom...] | L4: [Custom...]
A5: ACC1004-2110-DSB-UGRD-DOVER | B5: ACC1004-2110-DSB-UGRD-DOVER | C5: Business Law | D5: 5 | E5: DSB | F5: 0 | G5: 0 | H5: 0 | I5: [Custom...] | J5: 23743 | K5: [Custom...] | L5: [Custom...]
A6: ACC1005-2110-DSB-UGRD-DOVER | B6: ACC1005-2110-DSB-UGRD-DOVER | C6: Foundations of Finance | D6: 5 | E6: DSB | F6: 0 | G6: 0 | H6: 0 | I6: [Custom...] | J6: 23743 | K6: [Custom...] | L6: [Custom...]
A7: ACC1106-2110-DSB-UGRD-DOVER | B7: ACC1106-2110-DSB-UGRD-DOVER | C7: Quantitative Analysis | D7: 5 | E7: DSB | F7: 0 | G7: 0 | H7: 0 | I7: [Custom...] | J7: 23743 | K7: [Custom...] | L7: [Custom...]
A8: ACC2001-2110-DSB-UGRD-DOVER | B8: ACC2001-2110-DSB-UGRD-DOVER | C8: Financial Accounting | D8: 5 | E8: DSB | F8: 0 | G8: 0 | H8: 0 | I8: [Custom...] | J8: 23743 | K8: [Custom...] | L8: [Custom...]
A9: ACC2002-2110-DSB-UGRD-DOVER | B9: ACC2002-2110-DSB-UGRD-DOVER | C9: Auditing | D9: 5 | E9: DSB | F9: 0 | G9: 0 | H9: 0 | I9: [Custom...] | J9: 23743 | K9: [Custom...] | L9: [Custom...]
A10: ACC2003-2110-DSB-UGRD-DOVER | B10: ACC2003-2110-DSB-UGRD-DOVER | C10: Company Law | D10: 5 | E10: DSB | F10: 0 | G10: 0 | H10: 0 | I10: [Custom...] | J10: 23743 | K10: [Custom...] | L10: [Custom...]
A11: ACC2004-2110-DSB-UGRD-DOVER | B11: ACC2004-2110-DSB-UGRD-DOVER | C11: Corporate Finance | D11: 5 | E11: DSB | F11: 0 | G11: 0 | H11: 0 | I11: [Custom...] | J11: 23743 | K11: [Custom...] | L11: [Custom...]
A12: ACC2103-2110-DSB-UGRD-DOVER | B12: ACC2103-2110-DSB-UGRD-DOVER | C12: Company and Securities Law | D12: 5 | E12: DSB | F12: 0 | G12: 0 | H12: 0 | I12: [Custom...] | J12: 23743 | K12: [Custom...] | L12: [Custom...]
A13: ACC2901-2110-DSB-UGRD-DOVER | B13: ACC2901-2110-DSB-UGRD-DOVER | C13: Value Added Programme 1 (Essentials of an Auditor) | D13: 2 | E13: DSB | F13: 0 | G13: 0 | H13: 0 | I13: [Custom...] | J13: 23743 | K13: [Custom...] | L13: [Custom...]
... A447: UXG2570-2110-ICT-UDGP-SP | B447: UXG2570-2110-ICT-UDGP-SP | C447: User Research 1 | D447: 5 | E447: ICT | F447: 0 | G447: 0 | H447: 0 | I447: [Custom...] | J447: 23743 | K447: [Custom...] | L447: [Custom...]

Sheet Time
A1: Timing
A2: 0700
A3: 0730
A4: 0800
A5: 0830
A6: 0900
A7: 0930
A8: 1000
A9: 1030
A10: 1100
A11: 1130
A12: 1200
... A32: 2200

Sheet Day
A1: Day
A2: Mon
A3: Tue
A4: Wed
A5: Thu
A6: Fri
A7: Sat
A8: Sun

Sheet Sheet2
A1: Name | B1: Host Key | C1: Email | D1: Named Availability | E1: Named Starts | F1: Named Usage | G1: PT? | H1: Department | I1: Shared With | J1: Shared With All | K1: Primary Suitabilities | L1: Other Suitabilities | M1: Contract Periods | N1: Maximum Periods | O1: Constraint Profiles
A2: CHONG JUN JIE . | B2: G12077 | D2: [Custom...] | E2: [Custom...] | F2: [Custom...] | G2: Unchecked | H2: SIT | I2: All | J2: Checked | K2: AEE1111 (NP), AEE1112 (NP), AEE1131 (NP), AEE1141 (NP), AEE1151 (NP), AEE1161 (NP), AEE1211 (NP), AEE1221 (NP), AEE1231 (NP), AEE1241 (NP), AEE1271 (NP), AEE1281 (NP), AEE2111 (NP), AEE2121 (NP), AEE2122 (NP), AEE2123 (NP), AEE2151 (NP), ASE1101 (DOVER), ASE1102 (DOVER), ASE1103 (DOVER), ASE1104 (DOVER), ASE1105 (DOVER), ASE1206 (DOVER), ASE1207 (DOVER), ASE1208 (DOVER), ASE1209 (DOVER), ASE1210 (DOVER), ASE1211 (DOVER), ASE1303 (DOVER), ASE1312 (DOVER), ASE1313 (DOVER), ASE1314 (DOVER), ASE1315 (DOVER), ASE1316 (DOVER), ASE1317 (DOVER), ASE2201 (DOVER), ASE2202 (DOVER), ASE2203 (DOVER), ASE2204 (DOVER), ASE2205 (DOVER), ASE2306 (DOVER), ASE2307 (DOVER), ASE2308 (DOVER), ASE2309 (DOVER), ASE2310 (DOVER), ASE3101 (DOVER), ASE3102 (DOVER), ASE3103 (DOVER), ASE3104 (DOVER), CVE1111 (DOVER), CVE1112 (DOVER), CVE1113 (DOVER), CVE1121 (DOVER), CVE1181 (DOVER), CVE1211 (DOVER), CVE1212 (DOVER), CVE1221 (DOVER), CVE1231 (DOVER), CVE1241 (DOVER), CVE1281 (DOVER), CVE2111 (DOVER), CVE2121 (DOVER), CVE2131 (DOVER), CVE2141 (DOVER), CVE2161 (DOVER), CVE2221 (DOVER), CVE2222 (DOVER), CVE2251 (DOVER), CVE2252 (DOVER), CVE2281 (DOVER), CVE2321 (DOVER), CVE2331 (DOVER), CVE2361 (DOVER), CVE2371 (DOVER), CVE2372 (DOVER), CVE3171 (DOVER), CVE3331 (DOVER), CVE3351 (DOVER), CVE3361 (DOVER), CVE3362 (DOVER), CVE3371 (DOVER), EDE1101 (SP), EDE1102 (SP), EDE1103 (SP), EDE1104 (SP), EDE1105 (SP), EEE6001 (NYP), EEE6002 (NYP), EEE6003 (NYP), EEE6004 (NYP), EEE6010 (NYP), EEE6100 (NYP), EPE1101 (NYP), EPE1102 (NYP), EPE1103 (NYP), EPE1105 (NYP), EPE1108 (NYP), EPE1109 (NYP), EPE1110 (NYP), EPE1111 (NYP), EPE2200 (NYP), EPE2201 (NYP), EPE2202 (NYP), EPE2203 (NYP), EPE2205 (NYP), EPE2206 (NYP), EPE2207 (NYP), EPE2208 (NYP), EPE2210 (NYP), EPE3200 (NYP), EPE3201 (NYP), EPE3202 (NYP), EPE3203 (NYP), EPE3204 (NYP), EPE3206 (NYP), EPE3207 (NYP), EPE3210 (NYP), EPE6001 (NYP), EPE6002 (NYP), EPE6003 (NYP), EPE6004 (NYP), EPE6005 (NYP), EPE6006 (NYP), EPE6007 (NYP), EPE6008 (NYP), EPE6009 (NYP), EPE6010 (NYP), EPE6100 (NYP), MEC1111 (NP), MEC1112 (NP), MEC1113 (NP), MEC1121 (NP), MEC1131 (NP), MEC1181 (NP), MEC1211 (NP), MEC1221 (NP), MEC1222 (NP), MEC1251 (NP), MEC1261 (NP), MEC1281 (NP), MEC2111 (NP), MEC2121 (NP), MEC2122 (NP), MEC2131 (NP), MEC2132 (NP), MEC2133 (NP), MEC2141 (NP), MME1011 (NYP), MME1021 (NYP), MME1031 (NYP), MME1051 (NYP), MME1052 (NYP), MME1111 (NYP), MME1112 (NYP), MME1121 (NYP), MME1122 (NYP), MME1131 (NYP), MME1141 (NYP), MME1151 (NYP), MME1152 (NYP), MME1161 (NYP), MME1171 (NYP), MME1231 (NYP), MME2121 (NYP), MME2131 (NYP), MME2141 (NYP), MME2142 (NYP), MME2151 (NYP), MME2152 (NYP), MME2153 (NYP), MME2161 (NYP), MME2171 (NYP), MME2181 (NYP), MME2182 (NYP), MME2183 (NYP), MME2184 (NYP), MME3001 (NYP), MME3111 (NYP), MME3151 (NYP), MME3152 (NYP), MME3153 (NYP), MME3161 (NYP), MME3191 (NYP), MNO1101 (NP), MNO1102 (NP), MNO1103 (NP), MNO1104 (NP), MNO1105 (NP), MNO1106 (NP), MNO1107 (NP), MNO1108 (NP), MNO1109 (NP), MNO1110 (NP), MNO2101 (NP), MNO2102 (NP), MNO2103 (NP), MNO2104 (NP), MNO2105 (NP), MNO2106 (NP), MNO2107 (NP), MNO2108 (NP), MNO2109 (NP), MNO2110 (NP), MNO2111 (NP), MNO2112 (NP), MNO3101 (NP), MNO3102 (NP), MNO3103 (NP), MNO3104 (NP), MNO3105 (NP), MNO3106 (NP), MNO3107 (NP), MNO3108 (NP), MNO3109 (NP), MNO3110 (NP), MNO3111 (NP), MNO3112 (NP), MNO3113 (NP), MNO3114 (NP), SEM1000 (SP), SEM1001 (SP), SEM1101 (SP), SEM1102 (SP), SEM1401 (SP), SEM1402 (SP), SEM1501 (SP), SEM1502 (SP), SEM1601 (SP), SEM1901 (SP), SEM1902 (SP), SEM2002 (SP), SEM2003 (SP), SEM2103 (SP), SEM2104 (SP), SEM2105 (SP), SEM2201 (SP), SEM2202 (SP), SEM2203 (SP), SEM2303 (SP), SEM2304 (SP), SEM2403 (SP), SEM2503 (SP), SEM2602 (SP), SEM2603 (SP), SEM2700 (SP), SEM3507 (SP), SEM3700 (SP), SEM3802 (SP), SEM4004 (SP), SEM4005 (SP), SEM4107 (SP), SEM4305 (SP), SEM4504 (SP), SEM4605 (SP), SEM4606 (SP), SEM4607 (SP), SEM4608 (SP), SEM4610 (SP), SIE1001 (DOVER), SIE1002 (DOVER), SIE1003 (DOVER), SIE1004 (DOVER), SIE1007 (DOVER), SIE1008 (DOVER), SIE1009 (DOVER), SIE1010 (DOVER), SIE1012 (DOVER), SIE2001 (DOVER), SIE2002 (DOVER), SIE2003 (DOVER), SIE2004 (DOVER), SIE2005 (DOVER), SIE2006 (DOVER), SIE2007 (DOVER), SIE2008 (DOVER), SIE2009 (DOVER), SIE2010 (DOVER), SIE2011 (DOVER), SIE2012 (DOVER), SIE2013 (DOVER), SIE2014 (DOVER), SIE2015 (DOVER), SIE2016 (DOVER), SIE2017 (DOVER), SIE2018 (DOVER), SIE2019 (DOVER), SIE2020 (DOVER), SIE2021 (DOVER), SIE2901 (DOVER), SIE3001 (DOVER), SIE3002 (DOVER), SIE3003 (DOVER), SIE3004 (DOVER), SIE3005 (DOVER), SIE3006 (DOVER), SIE3007 (DOVER), SIE3008 (DOVER), SIE3009 (DOVER), SIE3010 (DOVER), SIE3011 (DOVER), SIE3012 (DOVER), SIE3013 (DOVER), SIE3014 (DOVER), SIE3015 (DOVER), SIE3016 (DOVER), SIE3023 (DOVER), SIE6001 (DOVER), SIE6003 (DOVER), SIE6006 (DOVER), SIE6009 (DOVER), SIE6012 (DOVER), SIE6014 (DOVER), SIE6015 (DOVER), SIE6016 (DOVER), SIE6017 (DOVER), SIE6018 (DOVER), SIE6020 (DOVER), SIE6021 (DOVER), SIE6022 (DOVER), SIE6023 (DOVER) | M2: 196 | N2: 196
A3: DEVENNEY KATE ELIZABET . | B3: G19032 | D3: [Custom...] | E3: [Custom...] | F3: [Custom...] | G3: Unchecked | H3: SIT | I3: All | J3: Checked | K3: DRG1001 (DOVER), DRG1002 (DOVER), DRG1901 (DOVER), DRG1902 (DOVER), DRG2001 (DOVER), DRG2002 (DOVER), DRG2003 (DOVER), DRG2901 (DOVER), DRG2902 (DOVER), DRG2903 (DOVER), DRG2904 (DOVER), DRG3001 (DOVER), DRG3002 (DOVER), DRG3003 (DOVER), DRG3004 (DOVER), DRG3801 (DOVER), DRG3901 (DOVER), DRG3902 (DOVER), DRG4001 (DOVER), DRG4002 (DOVER), DRG4801 (DOVER), DRG4901 (DOVER), DRG6101 (DOVER), DRG6102 (DOVER), DRG6103 (DOVER), DRG6105 (DOVER), DRG6106 (DOVER), DRG6107 (DOVER), DTN1001 (DOVER), DTN1004 (DOVER), DTN1005 (DOVER), DTN2001 (DOVER), DTN2002 (DOVER), HSC1001 (DOVER), HSC1002 (DOVER), HSC1004 (DOVER), HSC1005 (DOVER), HSC1006 (DOVER), HSC1101 (DOVER), HSC1102 (DOVER), HSC1103 (DOVER), HSC1104 (DOVER), HSC1105 (DOVER), HSC1701 (DOVER), HSC1704 (DOVER), HSC1706 (DOVER), HSC2001 (DOVER), HSC2002 (DOVER), HSC2007 (DOVER), HSC3001 (DOVER), HSC3002 (DOVER), HSC3005 (DOVER), HSC4005 (DOVER), HSC6001 (DOVER), HSC6002 (DOVER), HSC6003 (DOVER), HSC6004 (DOVER), HSC6008 (DOVER), IDC6102 (DOVER), NUR1002 (DOVER), NUR1004 (DOVER), NUR1005 (DOVER), NUR1006 (DOVER), NUR1007 (DOVER), NUR1008 (DOVER), NUR1009 (DOVER), NUR1010 (DOVER), NUR1011 (DOVER), NUR1012-HSS-DOVER, NUR1013 (DOVER), NUR1014 (DOVER), NUR2001 (DOVER), NUR2002 (DOVER), NUR2801 (DOVER), NUR2901 (DOVER), NUR3001 (DOVER), NUR3002 (DOVER), NUR3003 (DOVER), OTY1006 (DOVER), OTY1007 (DOVER), OTY1008 (DOVER), OTY1101 (DOVER), OTY1102 (DOVER), OTY1905 (DOVER), OTY2002 (DOVER), OTY2003 (DOVER), OTY2006 (DOVER), OTY2007 (DOVER), OTY2008 (DOVER), OTY2101 (DOVER), OTY2105 (DOVER), OTY2909 (DOVER), OTY3002 (DOVER), OTY3003 (DOVER), OTY3004 (DOVER), OTY3005 (DOVER), OTY3008 (DOVER), OTY3101 (DOVER), OTY3906 (DOVER), OTY3907 (DOVER), OTY3916 (DOVER), OTY3917 (DOVER), OTY4005 (DOVER), OTY4103 (DOVER), OTY4901 (DOVER), OTY4911 (DOVER), PTY1001 (DOVER), PTY1002 (DOVER), PTY1007 (DOVER), PTY1008 (DOVER), PTY1009 (DOVER), PTY1010 (DOVER), PTY1707 (DOVER), PTY2001 (DOVER), PTY2002 (DOVER), PTY2003 (DOVER), PTY2004 (DOVER), PTY2005 (DOVER), PTY2006 (DOVER), PTY2007 (DOVER), PTY2008 (DOVER), PTY2009 (DOVER), PTY2010 (DOVER), PTY2011 (DOVER), PTY2012 (DOVER), PTY2013 (DOVER), PTY3002 (DOVER), PTY3003 (DOVER), PTY3004 (DOVER), PTY3006 (DOVER), PTY3007 (DOVER), PTY3008 (DOVER), PTY3009 (DOVER), PTY3010 (DOVER), PTY3801 (DOVER), PTY3901 (DOVER), PTY4005 (DOVER), PTY4801 (DOVER), PTY4901 (DOVER), RTY1001 (DOVER), RTY1901 (DOVER), RTY1902 (DOVER), RTY2001 (DOVER), RTY2003 (DOVER), RTY2004 (DOVER), RTY2005 (DOVER), RTY2901 (DOVER), RTY2902 (DOVER), RTY3001 (DOVER), RTY3002 (DOVER), RTY3003 (DOVER), RTY3004 (DOVER), RTY3801 (DOVER), RTY3901 (DOVER), RTY3904 (DOVER), RTY4001 (DOVER), RTY4002 (DOVER), RTY4801 (DOVER), RTY4901 (DOVER), RTY4905 (DOVER), SLT1101 (DOVER) | M3: 196 | N3: 196
A4: FTE INSTRUCTOR1 | B4: TMPFTE01 | D4: [Custom...] | E4: [Custom...] | F4: [Custom...] | G4: Unchecked | H4: SIT | I4: All | J4: Checked | K4: CHE1011 (NP), CHE1012 (NP), CHE1013 (NP), CHE1014 (NP), CHE1015 (NP), CHE1021 (NP), CHE1022 (NP), CHE1023 (NP), CHE2011 (NP), CHE2012 (NP), CHE2013 (NP), CHE2014 (NP), CHE2015 (NP), CHE2016 (NP), CHE2017 (NP), CHE2021 (NP), CHE2022 (NP), CHE2023 (NP), CHE2024 (NP), CHE2025 (NP), CHE2031 (NP), CHE2033 (NP), CHE3021 (NP), CHE3022 (NP), CHE3023 (NP), CHE3025 (NP), CHE3031 (NP), CHE6001 (DOVER), CHE6002-CEFT-DOVER, CHE6003 (DOVER), CHE6004-CEFT-DOVER, CHE6005 (DOVER), CHE6006 (DOVER), CHE6011-CEFT-DOVER, CHE6013-CEFT-DOVER, CHE6018 (DOVER), CHE6019 (DOVER), FTE1011 (DOVER), FTE1013 (DOVER), FTE1014 (DOVER), FTE1015 (DOVER), FTE1016 (DOVER), FTE1021 (DOVER), FTE1022 (DOVER), FTE1023 (DOVER), FTE1024 (DOVER), FTE2011 (DOVER), FTE2012 (DOVER), FTE2013 (DOVER), FTE2014 (DOVER), FTE2015 (DOVER), FTE2021 (DOVER), FTE2022 (DOVER), FTE2023 (DOVER), FTE2024 (DOVER), FTE2025 (DOVER), FTE2031 (DOVER), FTE2032 (DOVER), FTE2033 (DOVER), FTE2034 (DOVER), FTE3011 (DOVER), FTE3012 (DOVER), FTE3013 (DOVER), FTE3014 (DOVER), FTE3021 (DOVER), FTE4012 (DOVER), FTE4021 (DOVER), FTE4022 (DOVER), FTE4101 (DOVER), FTE4102 (DOVER), FTE4103 (DOVER), FTE4104 (DOVER), FTE4105 (DOVER), IDC6101 (DOVER), IMC6101 (DOVER), PHE1011 (DOVER), PHE1012 (DOVER), PHE1013 (DOVER), PHE1014 (DOVER), PHE1015 (DOVER), PHE1021 (DOVER), PHE1022 (DOVER), PHE1023 (DOVER), PHE1024 (DOVER), PHE1031 (DOVER), PHE1032 (DOVER), PHE1033 (DOVER), PHE1034 (DOVER), PHE1036 (DOVER), PHE1125 (DOVER), PHE1133 (DOVER), PHE1135 (DOVER), PHE2011 (DOVER), PHE2012 (DOVER), PHE2014 (DOVER), PHE2016 (DOVER), PHE2031 (DOVER), PHE2032 (DOVER), PHE2035 (DOVER), PHE2036 (DOVER), PHE2113 (DOVER), PHE2133 (DOVER), PHE2134 (DOVER), PHE2137 (DOVER), PHE2138 (DOVER), PHE2139 (DOVER), PHE3011 (DOVER), PHE3013 (DOVER), PHE3015 (DOVER), PHE3016 (DOVER), PHE3018 (DOVER), PHE3019 (DOVER), PHE3021 (DOVER), PHE3022 (DOVER), PHE3032 (DOVER), PHE3112 (DOVER), PHE3117 (DOVER), PHE4011 (DOVER), PHE4012 (DOVER), PHE4013 (DOVER), PHE4014 (DOVER), TCE1011 (DOVER), TCE1012 (DOVER), TCE1013 (DOVER), TCE1014 (DOVER), TCE1015 (DOVER) | M4: 196 | N4: 196
A5: GAN LIAN CHAI . | B5: G21119 | D5: [Custom...] | E5: [Custom...] | F5: [Custom...] | G5: Unchecked | H5: SIT | I5: All | J5: Checked | M5: 196 | N5: 196
A6: GERALD WONG HAN FENG . | B6: G21143 | D6: [Custom...] | E6: [Custom...] | F6: [Custom...] | G6: Unchecked | H6: SIT | I6: All | J6: Checked | M6: 196 | N6: 196
A7: GOH GHEE MING . | B7: H02012 | D7: [Custom...] | E7: [Custom...] | F7: [Custom...] | G7: Unchecked | H7: SIT | I7: All | J7: Checked | M7: 196 | N7: 196
A8: JESMOND HONG . | B8: G13034 | D8: [Custom...] | E8: [Custom...] | F8: [Custom...] | G8: Unchecked | H8: SIT | I8: All | J8: Checked | M8: 196 | N8: 196
A9: JOANNA LUO . | B9: G15061 | D9: [Custom...] | E9: [Custom...] | F9: [Custom...] | G9: Unchecked | H9: SIT | I9: All | J9: Checked | M9: 196 | N9: 196
A10: JOSEPH GREENER . | B10: G20014 | D10: [Custom...] | E10: [Custom...] | F10: [Custom...] | G10: Unchecked | H10: SIT | I10: All | J10: Checked | M10: 196 | N10: 196
